Workbook

Sheet Instrucciones
B2: KLIXMANT — Clasificación de Inventario: Tela Antigua vs. Tela Nueva
B4: ¿Para qué sirve este archivo?
B5: Es tu inventario actual (mismas 251 referencias) con dos columnas nuevas para que, a medida que revises cada prenda al tacto, marques cuántas unidades de esa referencia son de tela antigua y cuántas son de tela nueva.
B7: Cómo usarlo (hoja 'Clasificación')
B8: 1. Ve fila por fila (ya vienen ordenadas por referencia, igual que tu inventario original).
B9: 2. En la columna E 'Tela antigua', escribe cuántas unidades de esa referencia son tela antigua.
B10: 3. En la columna F 'Tela nueva', escribe cuántas unidades son tela nueva.
B11: 4. La columna G 'Diferencia' se calcula sola: si queda en 0, esa fila ya está 100% clasificada.
B12: 5. Si la columna G se pone en rojo, esa referencia no suma bien contra el stock total — revísala.
B13: 6. Puedes dejar en blanco las referencias que aún no revises; solo cuentan las que ya marcaste.
B14: 7. La hoja 'Resumen' se actualiza sola con los totales generales y el avance de la clasificación.
B16: Convención de color
... B18: El resto de columnas son de solo lectura: vienen de tu inventario original.

Sheet Clasificación
A1: Clasificación de inventario — Tela antigua vs. Tela nueva
A2: ID | B2: Nombre | C2: Referencia | D2: Stock total empresa | E2: Tela antigua | F2: Tela nueva | G2: Diferencia | H2: Estado
A3: 6896 | B3: BCVL ML NEGRO L | C3: BCVLMLNEGROL | D3: 2 | E3: 2 | G3: =D3-E3-F3 -> 0 | H3: =IF(AND(E3="",F3=""),"Sin revisar",IF(G3=0,"Clasificado","Revisar")) -> Clasificado
A4: 6898 | B4: BCVL ML NEGRO 2XL | C4: BCVLMLNEGRO2XL | D4: 1 | E4: 1 | G4: =D4-E4-F4 -> 0 | H4: =IF(AND(E4="",F4=""),"Sin revisar",IF(G4=0,"Clasificado","Revisar")) -> Clasificado
A5: 6899 | B5: BCVL ML NEGRO 3XL | C5: BCVLMLNEGRO3XL | D5: 2 | E5: 2 | G5: =D5-E5-F5 -> 0 | H5: =IF(AND(E5="",F5=""),"Sin revisar",IF(G5=0,"Clasificado","Revisar")) -> Clasificado
A6: 6940 | B6: BCVL ML GRIS JASPE M | C6: BCVLMLGRISJASPEM | D6: 1 | E6: 1 | G6: =D6-E6-F6 -> 0 | H6: =IF(AND(E6="",F6=""),"Sin revisar",IF(G6=0,"Clasificado","Revisar")) -> Clasificado
A7: 6956 | B7: BCVL ML ROJO L | C7: BCVLMLROJOL | D7: 1 | E7: 1 | G7: =D7-E7-F7 -> 0 | H7: =IF(AND(E7="",F7=""),"Sin revisar",IF(G7=0,"Clasificado","Revisar")) -> Clasificado
A8: 6970 | B8: BCVL ML ROSADO M | C8: BCVLMLROSADOM | D8: 1 | E8: 1 | G8: =D8-E8-F8 -> 0 | H8: =IF(AND(E8="",F8=""),"Sin revisar",IF(G8=0,"Clasificado","Revisar")) -> Clasificado
A9: 6984 | B9: BCVL ML VERDE AGUA S | C9: BCVLMLVERDEAGUAS | D9: 1 | E9: 1 | G9: =D9-E9-F9 -> 0 | H9: =IF(AND(E9="",F9=""),"Sin revisar",IF(G9=0,"Clasificado","Revisar")) -> Clasificado
A10: 6985 | B10: BCVL ML VERDE AGUA M | C10: BCVLMLVERDEAGUAM | D10: 1 | E10: 1 | G10: =D10-E10-F10 -> 0 | H10: =IF(AND(E10="",F10=""),"Sin revisar",IF(G10=0,"Clasificado","Revisar")) -> Clasificado
A11: 7014 | B11: BCVL ML BLANCO S | C11: BCVLMLBLANCOS | D11: 2 | E11: 2 | G11: =D11-E11-F11 -> 0 | H11: =IF(AND(E11="",F11=""),"Sin revisar",IF(G11=0,"Clasificado","Revisar")) -> Clasificado
A12: 7017 | B12: BCVL ML BLANCO XL | C12: BCVLMLBLANCOXL | D12: 1 | E12: 1 | G12: =D12-E12-F12 -> 0 | H12: =IF(AND(E12="",F12=""),"Sin revisar",IF(G12=0,"Clasificado","Revisar")) -> Clasificado
A13: 7030 | B13: BCVL ML AZUL REY M | C13: BCVLMLAZULREYM | D13: 1 | E13: 1 | G13: =D13-E13-F13 -> 0 | H13: =IF(AND(E13="",F13=""),"Sin revisar",IF(G13=0,"Clasificado","Revisar")) -> Clasificado
A14: 7062 | B14: BCVL ML MOSTAZA XL | C14: BCVLMLMOSTAZAXL | D14: 2 | E14: 2 | G14: =D14-E14-F14 -> 0 | H14: =IF(AND(E14="",F14=""),"Sin revisar",IF(G14=0,"Clasificado","Revisar")) -> Clasificado
... A47: 8021 | B47: B4 ML R GRIS JASPE L | C47: B4MLRGRISJASPEL | D47: 0 | E47: 0 | G47: =D47-E47-F47 -> 0 | H47: =IF(AND(E47="",F47=""),"Sin revisar",IF(G47=0,"Clasificado","Revisar")) -> Clasificado
A48: 8022 | B48: B4 ML R GRIS JASPE XL | C48: B4MLRGRISJASPEXL | D48: 11 | E48: 8 | F48: 3 | G48: =D48-E48-F48 -> 0 | H48: =IF(AND(E48="",F48=""),"Sin revisar",IF(G48=0,"Clasificado","Revisar")) -> Clasificado
A49: 8023 | B49: B4 ML R GRIS JASPE 2XL | C49: B4MLRGRISJASPE2XL | D49: 3 | E49: 3 | G49: =D49-E49-F49 -> 0 | H49: =IF(AND(E49="",F49=""),"Sin revisar",IF(G49=0,"Clasificado","Revisar")) -> Clasificado
A50: 8050 | B50: B4 ML R ROSADO M | C50: B4MLRROSADOM | D50: 19 | E50: 19 | G50: =D50-E50-F50 -> 0 | H50: =IF(AND(E50="",F50=""),"Sin revisar",IF(G50=0,"Clasificado","Revisar")) -> Clasificado
A51: 8051 | B51: B4 ML R ROSADO L | C51: B4MLRROSADOL | D51: 1 | E51: 1 | G51: =D51-E51-F51 -> 0 | H51: =IF(AND(E51="",F51=""),"Sin revisar",IF(G51=0,"Clasificado","Revisar")) -> Clasificado
A52: 8052 | B52: B4 ML R ROSADO XL | C52: B4MLRROSADOXL | D52: 2 | E52: 2 | G52: =D52-E52-F52 -> 0 | H52: =IF(AND(E52="",F52=""),"Sin revisar",IF(G52=0,"Clasificado","Revisar")) -> Clasificado
A53: 8053 | B53: B4 ML R ROSADO 2XL | C53: B4MLRROSADO2XL | D53: 2 | E53: 2 | G53: =D53-E53-F53 -> 0 | H53: =IF(AND(E53="",F53=""),"Sin revisar",IF(G53=0,"Clasificado","Revisar")) -> Clasificado
A54: 8066 | B54: B4 ML R VERDE AGUA L | C54: B4MLRVERDEAGUAL | D54: 0 | E54: 0 | G54: =D54-E54-F54 -> 0 | H54: =IF(AND(E54="",F54=""),"Sin revisar",IF(G54=0,"Clasificado","Revisar")) -> Clasificado
A55: 8067 | B55: B4 ML R VERDE AGUA XL | C55: B4MLRVERDEAGUAXL | D55: 1 | E55: 1 | G55: =D55-E55-F55 -> 0 | H55: =IF(AND(E55="",F55=""),"Sin revisar",IF(G55=0,"Clasificado","Revisar")) -> Clasificado
A56: 8068 | B56: B4 ML R VERDE AGUA 2XL | C56: B4MLRVERDEAGUA2XL | D56: 1 | E56: 1 | G56: =D56-E56-F56 -> 0 | H56: =IF(AND(E56="",F56=""),"Sin revisar",IF(G56=0,"Clasificado","Revisar")) -> Clasificado
A57: 8069 | B57: B4 ML R VERDE AGUA 3XL | C57: B4MLRVERDEAGUA3XL | D57: 1 | E57: 1 | G57: =D57-E57-F57 -> 0 | H57: =IF(AND(E57="",F57=""),"Sin revisar",IF(G57=0,"Clasificado","Revisar")) -> Clasificado
A58: 8079 | B58: B4 ML R AZUL OSCURO S | C58: B4MLRAZULOSCUROS | D58: 0 | F58: 1 | G58: =D58-E58-F58 -> -1 | H58: =IF(AND(E58="",F58=""),"Sin revisar",IF(G58=0,"Clasificado","Revisar")) -> Revisar
A59: 8080 | B59: B4 ML R AZUL OSCURO M | C59: B4MLRAZULOSCUROM | D59: 0 | E59: 0 | G59: =D59-E59-F59 -> 0 | H59: =IF(AND(E59="",F59=""),"Sin revisar",IF(G59=0,"Clasificado","Revisar")) -> Clasificado
A60: 8081 | B60: B4 ML R AZUL OSCURO L | C60: B4MLRAZULOSCUROL | D60: 0 | E60: 0 | G60: =D60-E60-F60 -> 0 | H60: =IF(AND(E60="",F60=""),"Sin revisar",IF(G60=0,"Clasificado","Revisar")) -> Clasificado
A61: 8082 | B61: B4 ML R AZUL OSCURO XL | C61: B4MLRAZULOSCUROXL | D61: 0 | E61: 0 | G61: =D61-E61-F61 -> 0 | H61: =IF(AND(E61="",F61=""),"Sin revisar",IF(G61=0,"Clasificado","Revisar")) -> Clasificado
A62: 8083 | B62: B4 ML R AZUL OSCURO 2XL | C62: B4MLRAZULOSCURO2XL | D62: 0 | E62: 0 | G62: =D62-E62-F62 -> 0 | H62: =IF(AND(E62="",F62=""),"Sin revisar",IF(G62=0,"Clasificado","Revisar")) -> Clasificado
A63: 8094 | B63: B4 ML R BLANCO S | C63: B4MLRBLANCOS | D63: 5 | F63: 5 | G63: =D63-E63-F63 -> 0 | H63: =IF(AND(E63="",F63=""),"Sin revisar",IF(G63=0,"Clasificado","Revisar")) -> Clasificado
A64: 8095 | B64: B4 ML R BLANCO M | C64: B4MLRBLANCOM | D64: 2 | F64: 2 | G64: =D64-E64-F64 -> 0 | H64: =IF(AND(E64="",F64=""),"Sin revisar",IF(G64=0,"Clasificado","Revisar")) -> Clasificado
A65: 8096 | B65: B4 ML R BLANCO L | C65: B4MLRBLANCOL | D65: 8 | F65: 2 | G65: =D65-E65-F65 -> 6 | H65: =IF(AND(E65="",F65=""),"Sin revisar",IF(G65=0,"Clasificado","Revisar")) -> Revisar
A66: 8097 | B66: B4 ML R BLANCO XL | C66: B4MLRBLANCOXL | D66: 1 | F66: 1 | G66: =D66-E66-F66 -> 0 | H66: =IF(AND(E66="",F66=""),"Sin revisar",IF(G66=0,"Clasificado","Revisar")) -> Clasificado
A67: 8108 | B67: B4 ML R AZUL REY XS | C67: B4MLRAZULREYXS | D67: 1 | E67: 1 | G67: =D67-E67-F67 -> 0 | H67: =IF(AND(E67="",F67=""),"Sin revisar",IF(G67=0,"Clasificado","Revisar")) -> Clasificado
A68: 8112 | B68: B4 ML R AZUL REY XL | C68: B4MLRAZULREYXL | D68: 7 | E68: 7 | G68: =D68-E68-F68 -> 0 | H68: =IF(AND(E68="",F68=""),"Sin revisar",IF(G68=0,"Clasificado","Revisar")) -> Clasificado
A69: 8124 | B69: B4 ML R AMARILLO S | C69: B4MLRAMARILLOS | D69: 5 | E69: 5 | G69: =D69-E69-F69 -> 0 | H69: =IF(AND(E69="",F69=""),"Sin revisar",IF(G69=0,"Clasificado","Revisar")) -> Clasificado
A70: 8139 | B70: B4 ML R MOSTAZA S | C70: B4MLRMOSTAZAS | D70: 12 | E70: 12 | G70: =D70-E70-F70 -> 0 | H70: =IF(AND(E70="",F70=""),"Sin revisar",IF(G70=0,"Clasificado","Revisar")) -> Clasificado
A71: 8140 | B71: B4 ML R MOSTAZA M | C71: B4MLRMOSTAZAM | D71: 29 | E71: 29 | G71: =D71-E71-F71 -> 0 | H71: =IF(AND(E71="",F71=""),"Sin revisar",IF(G71=0,"Clasificado","Revisar")) -> Clasificado
A72: 8141 | B72: B4 ML R MOSTAZA L | C72: B4MLRMOSTAZAL | D72: 20 | E72: 20 | G72: =D72-E72-F72 -> 0 | H72: =IF(AND(E72="",F72=""),"Sin revisar",IF(G72=0,"Clasificado","Revisar")) -> Clasificado
...

Sheet Resumen
A1: Resumen de clasificación
A3: Referencias totales (filas) | B3: =COUNTA(Clasificación!C3:C254) -> 252
A4: Unidades totales en inventario | B4: =SUM(Clasificación!D3:D254) -> 1884
A5: Unidades tela antigua | B5: =SUM(Clasificación!E3:E254) -> 1851
A6: Unidades tela nueva | B6: =SUM(Clasificación!F3:F254) -> 33
A7: Unidades sin clasificar todavía | B7: =B4-B5-B6 -> 0
A8: % tela antigua sobre lo clasificado | B8: =IFERROR(B5/(B5+B6),0) -> 0.98248408
A9: % tela nueva sobre lo clasificado | B9: =IFERROR(B6/(B5+B6),0) -> 0.017515924
A10: Referencias ya clasificadas (Diferencia=0) | B10: =COUNTIF(Clasificación!H3:H254,"Clasificado") -> 247
A11: Referencias por revisar (no suman bien) | B11: =COUNTIF(Clasificación!H3:H254,"Revisar") -> 5
A12: Referencias sin revisar aún | B12: =COUNTIF(Clasificación!H3:H254,"Sin revisar") -> 0
A13: % de avance de la clasificación | B13: =IFERROR((B3-B12)/B3,0) -> 1
A16: Nota: esta hoja se actualiza sola a medida que llenas las columnas 'Tela antigua' y 'Tela nueva' en la hoja 'Clasificación'. Úsala para saber cuánto llevas del conteo.

Sheet Inventario_de_Telas
A1: Inventario de telas — Tela antigua vs. Tela nueva (metros)
A2: Tela | B2: Color | C2: Tipo de tela | D2: Cantidad inicial (mts) | E2: Cantidad medida ahora (mts) | F2: Diferencia vs. inicial (mts) | G2: % vs. inicial
A3: BUDA | B3: NEGRO | C3: =IF(OR(A3="CATAR",A3="COTTON"),"Tela nueva","Tela antigua") -> Tela antigua | D3: 160 | E3: 160 | F3: =IF(E3="","",IF(D3="","Sin inicial",D3-E3)) -> 0 | G3: =IF(E3="","",IF(OR(D3="",D3=0),"Nuevo color",E3/D3)) -> 1
A4: BUDA | B4: BLANCO | C4: =IF(OR(A4="CATAR",A4="COTTON"),"Tela nueva","Tela antigua") -> Tela antigua | D4: 67 | E4: 67 | F4: =IF(E4="","",IF(D4="","Sin inicial",D4-E4)) -> 0 | G4: =IF(E4="","",IF(OR(D4="",D4=0),"Nuevo color",E4/D4)) -> 1
A5: COTTON | B5: GRIS | C5: =IF(OR(A5="CATAR",A5="COTTON"),"Tela nueva","Tela antigua") -> Tela nueva | D5: 28 | E5: 40.4 | F5: =IF(E5="","",IF(D5="","Sin inicial",D5-E5)) -> -12.4 | G5: =IF(E5="","",IF(OR(D5="",D5=0),"Nuevo color",E5/D5)) -> 1.4428571
A6: CENTAURO | B6: VERDE OSCURO | C6: =IF(OR(A6="CATAR",A6="COTTON"),"Tela nueva","Tela antigua") -> Tela antigua | D6: 62 | E6: 62 | F6: =IF(E6="","",IF(D6="","Sin inicial",D6-E6)) -> 0 | G6: =IF(E6="","",IF(OR(D6="",D6=0),"Nuevo color",E6/D6)) -> 1
A7: CENTAURO | B7: CELESTE | C7: =IF(OR(A7="CATAR",A7="COTTON"),"Tela nueva","Tela antigua") -> Tela antigua | D7: 50 | E7: 50 | F7: =IF(E7="","",IF(D7="","Sin inicial",D7-E7)) -> 0 | G7: =IF(E7="","",IF(OR(D7="",D7=0),"Nuevo color",E7/D7)) -> 1
A8: CATAR | B8: CELESTE | C8: =IF(OR(A8="CATAR",A8="COTTON"),"Tela nueva","Tela antigua") -> Tela nueva | D8: 0 | E8: 59.5 | F8: =IF(E8="","",IF(D8="","Sin inicial",D8-E8)) -> -59.5 | G8: =IF(E8="","",IF(OR(D8="",D8=0),"Nuevo color",E8/D8)) -> Nuevo color
A9: CATAR | B9: BLANCO | C9: =IF(OR(A9="CATAR",A9="COTTON"),"Tela nueva","Tela antigua") -> Tela nueva | D9: 0 | E9: 66.85 | F9: =IF(E9="","",IF(D9="","Sin inicial",D9-E9)) -> -66.85 | G9: =IF(E9="","",IF(OR(D9="",D9=0),"Nuevo color",E9/D9)) -> Nuevo color
A10: CATAR | B10: GRIS OSCURO | C10: =IF(OR(A10="CATAR",A10="COTTON"),"Tela nueva","Tela antigua") -> Tela nueva | D10: 50 | E10: 48 | F10: =IF(E10="","",IF(D10="","Sin inicial",D10-E10)) -> 2 | G10: =IF(E10="","",IF(OR(D10="",D10=0),"Nuevo color",E10/D10)) -> 0.96
A11: CATAR | B11: NEGRO | C11: =IF(OR(A11="CATAR",A11="COTTON"),"Tela nueva","Tela antigua") -> Tela nueva | D11: 35.6 | E11: 98.1 | F11: =IF(E11="","",IF(D11="","Sin inicial",D11-E11)) -> -62.5 | G11: =IF(E11="","",IF(OR(D11="",D11=0),"Nuevo color",E11/D11)) -> 2.755618
A12: CATAR | B12: ROJO | C12: =IF(OR(A12="CATAR",A12="COTTON"),"Tela nueva","Tela antigua") -> Tela nueva | D12: 45 | E12: 45 | F12: =IF(E12="","",IF(D12="","Sin inicial",D12-E12)) -> 0 | G12: =IF(E12="","",IF(OR(D12="",D12=0),"Nuevo color",E12/D12)) -> 1
A13: CATAR | B13: AZUL OSCURO | C13: =IF(OR(A13="CATAR",A13="COTTON"),"Tela nueva","Tela antigua") -> Tela nueva | D13: 30 | E13: 71 | F13: =IF(E13="","",IF(D13="","Sin inicial",D13-E13)) -> -41 | G13: =IF(E13="","",IF(OR(D13="",D13=0),"Nuevo color",E13/D13)) -> 2.3666667
A14: CENTAURO | B14: MOSTAZA | C14: =IF(OR(A14="CATAR",A14="COTTON"),"Tela nueva","Tela antigua") -> Tela antigua | D14: 40 | E14: 40 | F14: =IF(E14="","",IF(D14="","Sin inicial",D14-E14)) -> 0 | G14: =IF(E14="","",IF(OR(D14="",D14=0),"Nuevo color",E14/D14)) -> 1
... A23: CENTAURO | B23: TERRACOTA | C23: =IF(OR(A23="CATAR",A23="COTTON"),"Tela nueva","Tela antigua") -> Tela antigua | D23: 10 | E23: 10 | F23: =IF(E23="","",IF(D23="","Sin inicial",D23-E23)) -> 0 | G23: =IF(E23="","",IF(OR(D23="",D23=0),"Nuevo color",E23/D23)) -> 1
A25: TOTALES | D25: =SUM(D3:D23) -> 754.6 | E25: =SUM(E3:E23) -> 994.85 | F25: =SUM(F3:F23) -> -240.25
A27: Total metros TELA NUEVA (Catar + Cotton) | B27: =SUMIF(C3:C23,"Tela nueva",D3:D23) -> 188.6 | C27: Cottone 229 g/ m2
A28: Total metros TELA ANTIGUA (Buda + Centauro) | B28: =SUMIF(C3:C23,"Tela antigua",D3:D23) -> 566 | C28: Centauro 178 g/ m2
A30: Marca en la columna dorada 'Cantidad medida ahora (mts)' lo que midas físicamente de cada color, así sea más o menos que el registro anterior. Si mides más de lo que había registrado, la Diferencia sale en negativo y el % vs. inicial sale por encima de 100% (resaltado en verde): es una señal de que hay más tela de la que pensabas, no un error. Si agregas un color nuevo sin cantidad inicial, el % mostrará 'Nuevo color' hasta que registres su cantidad inicial en la columna D.
